2018-03-13 14:50:20 ERROR (MainThread) [homeassistant.components.binary_sensor] Error while setting up platform netatmo
Traceback (most recent call last):
  File "/usr/lib/python3.6/site-packages/homeassistant/helpers/entity_platform.py", line 82, in async_setup
    SLOW_SETUP_MAX_WAIT, loop=hass.loop)
  File "/usr/lib/python3.6/asyncio/tasks.py", line 358, in wait_for
    return fut.result()
  File "/usr/lib/python3.6/asyncio/futures.py", line 245, in result
    raise self._exception
  File "/usr/lib/python3.6/concurrent/futures/thread.py", line 56, in run
    result = self.fn(*self.args, **self.kwargs)
  File "/usr/lib/python3.6/site-packages/homeassistant/components/binary_sensor/netatmo.py", line 75, in setup_platform
    if not data.get_camera_names():
  File "/usr/lib/python3.6/site-packages/homeassistant/components/netatmo.py", line 84, in get_camera_names
    self.update()
  File "/usr/lib/python3.6/site-packages/homeassistant/util/__init__.py", line 319, in wrapper
    result = method(*args, **kwargs)
  File "/usr/lib/python3.6/site-packages/homeassistant/components/netatmo.py", line 115, in update
    self.camera_data = lnetatmo.CameraData(self.auth, size=100)
  File "/usr/lib/python3.6/site-packages/smart_home/Camera.py", line 78, in __init__
    self.default_camera = list(self.cameras[self.default_home].values())[0]
IndexError: list index out of range
2018-03-13 14:50:20 ERROR (MainThread) [homeassistant.components.camera] Error while setting up platform netatmo
Traceback (most recent call last):
  File "/usr/lib/python3.6/site-packages/homeassistant/helpers/entity_platform.py", line 82, in async_setup
    SLOW_SETUP_MAX_WAIT, loop=hass.loop)
  File "/usr/lib/python3.6/asyncio/tasks.py", line 358, in wait_for
    return fut.result()
  File "/usr/lib/python3.6/asyncio/futures.py", line 245, in result
    raise self._exception
  File "/usr/lib/python3.6/concurrent/futures/thread.py", line 56, in run
    result = self.fn(*self.args, **self.kwargs)
  File "/usr/lib/python3.6/site-packages/homeassistant/components/camera/netatmo.py", line 42, in setup_platform
    for camera_name in data.get_camera_names():
  File "/usr/lib/python3.6/site-packages/homeassistant/components/netatmo.py", line 84, in get_camera_names
    self.update()
  File "/usr/lib/python3.6/site-packages/homeassistant/util/__init__.py", line 319, in wrapper
    result = method(*args, **kwargs)
  File "/usr/lib/python3.6/site-packages/homeassistant/components/netatmo.py", line 115, in update
    self.camera_data = lnetatmo.CameraData(self.auth, size=100)
  File "/usr/lib/python3.6/site-packages/smart_home/Camera.py", line 78, in __init__
    self.default_camera = list(self.cameras[self.default_home].values())[0]
IndexError: list index out of range
2018-03-13 14:50:43 WARNING (MainThread) [homeassistant.components.sensor] Setup of platform gearbest is taking over 10 seconds.
2018-03-13 14:51:11 WARNING (SyncWorker_15) [netdisco.ssdp] Found malformed XML at http://192.168.0.20:9080: status=ok
2018-03-13 14:51:15 WARNING (SyncWorker_15) [netdisco.ssdp] Error fetching description at http://192.168.0.50:45555/wps_device.xml
2018-03-13 14:51:41 WARNING (MainThread) [homeassistant.helpers.entity] Update of binary_sensor.door_window_sensor_158d0001b95bf4 is taking over 10 seconds
2018-03-13 14:51:41 ERROR (SyncWorker_4) [xiaomi_gateway] Cannot connect to Gateway
2018-03-13 14:51:41 ERROR (SyncWorker_4) [xiaomi_gateway] No data in response from hub None
2018-03-13 14:52:43 WARNING (MainThread) [homeassistant.helpers.entity] Update of binary_sensor.door_window_sensor_158d0001b95bf4 is taking over 10 seconds
2018-03-13 14:52:43 ERROR (SyncWorker_4) [xiaomi_gateway] Cannot connect to Gateway
2018-03-13 14:52:43 ERROR (SyncWorker_4) [xiaomi_gateway] No data in response from hub None
